<?xml version="1.0" encoding="utf-8"?>
<!-- This URDF was automatically created by SolidWorks to URDF Exporter! Originally created by Stephen Brawner (brawner@gmail.com) 
     Commit Version: 1.6.0-1-g15f4949  Build Version: 1.6.7594.29634
     For more information, please see http://wiki.ros.org/sw_urdf_exporter -->
<robot
  name="autocar_urdf">
  <link
    name="base_link">
    <inertial>
      <origin
        xyz="-0.0082217 -0.015323 -0.13715"
        rpy="0 0 0" />
      <mass
        value="4.8424" />
      <inertia
        ixx="0.031547"
        ixy="-1.1952E-06"
        ixz="-0.0018897"
        iyy="0.098519"
        iyz="-4.9071E-07"
        izz="0.11312" />
    </inertial>
    <visual>
      <origin
        xyz="0 0 0"
        rpy="0 0 0" />
      <geometry>
        <mesh
          filename="package://autocar_urdf/meshes/visual/base_link.STL" />
      </geometry>
      <material
        name="">
        <color
          rgba="0.79216 0.81961 0.93333 1" />
      </material>
    </visual>
    <collision>
      <origin
        xyz="0 0 0"
        rpy="0 0 0" />
      <geometry>
        <mesh
          filename="package://autocar_urdf/meshes/visual/base_link.STL" />
      </geometry>
    </collision>
  </link>
  <link
    name="head_left_link">
    <inertial>
      <origin
        xyz="-5.5511E-17 0.023901 -0.02621"
        rpy="0 0 0" />
      <mass
        value="0.054143" />
      <inertia
        ixx="4.1055E-05"
        ixy="1.8886E-20"
        ixz="3.7564E-22"
        iyy="2.1346E-05"
        iyz="-1.5617E-07"
        izz="3.2352E-05" />
    </inertial>
    <visual>
      <origin
        xyz="0 0 0"
        rpy="0 0 0" />
      <geometry>
        <mesh
          filename="package://autocar_urdf/meshes/visual/head_left_link.STL" />
      </geometry>
      <material
        name="">
        <color
          rgba="0.79216 0.81961 0.93333 1" />
      </material>
    </visual>
    <collision>
      <origin
        xyz="0 0 0"
        rpy="0 0 0" />
      <geometry>
        <mesh
          filename="package://autocar_urdf/meshes/visual/head_left_link.STL" />
      </geometry>
    </collision>
  </link>
  <joint
    name="head_left_link_joint"
    type="revolute">
    <origin
      xyz="0.37142 0.23399 -0.1695"
      rpy="0 0 0" />
    <parent
      link="base_link" />
    <child
      link="head_left_link" />
    <axis
      xyz="0 0 -1" />
    <limit
      lower="-0.785"
      upper="0.785"
      effort="0"
      velocity="0" />
  </joint>
  <link
    name="head_left_wheel">
    <inertial>
      <origin
        xyz="-6.2782E-06 0.0016644 2.0084E-05"
        rpy="0 0 0" />
      <mass
        value="7.6662" />
      <inertia
        ixx="0.063692"
        ixy="-1.9954E-07"
        ixz="7.4231E-08"
        iyy="0.11066"
        iyz="2.6493E-08"
        izz="0.063692" />
    </inertial>
    <visual>
      <origin
        xyz="0 0 0"
        rpy="0 0 0" />
      <geometry>
        <mesh
          filename="package://autocar_urdf/meshes/visual/head_left_wheel.STL" />
      </geometry>
      <material
        name="">
        <color
          rgba="0 0 0 0.8" />
      </material>
    </visual>
    <collision>
      <origin
        xyz="0 0 0"
        rpy="0 0 0" />
      <geometry>
        <mesh
          filename="package://autocar_urdf/meshes/visual/head_left_wheel.STL" />
      </geometry>
    </collision>
  </link>
  <joint
    name="head_left_wheel_joint"
    type="continuous">
    <origin
      xyz="0 0.066 -0.026"
      rpy="0 0 0" />
    <parent
      link="head_left_link" />
    <child
      link="head_left_wheel" />
    <axis
      xyz="0 -1 0" />
  </joint>
  <link
    name="head_right_link">
    <inertial>
      <origin
        xyz="1.1102E-16 -0.023901 -0.02621"
        rpy="0 0 0" />
      <mass
        value="0.054143" />
      <inertia
        ixx="4.1055E-05"
        ixy="1.8982E-20"
        ixz="-3.0255E-22"
        iyy="2.1346E-05"
        iyz="1.5617E-07"
        izz="3.2352E-05" />
    </inertial>
    <visual>
      <origin
        xyz="0 0 0"
        rpy="0 0 0" />
      <geometry>
        <mesh
          filename="package://autocar_urdf/meshes/visual/head_right_link.STL" />
      </geometry>
      <material
        name="">
        <color
          rgba="0.79216 0.81961 0.93333 1" />
      </material>
    </visual>
    <collision>
      <origin
        xyz="0 0 0"
        rpy="0 0 0" />
      <geometry>
        <mesh
          filename="package://autocar_urdf/meshes/visual/head_right_link.STL" />
      </geometry>
    </collision>
  </link>
  <joint
    name="head_right_link_joint"
    type="revolute">
    <origin
      xyz="0.37142 -0.23401 -0.1695"
      rpy="0 0 0" />
    <parent
      link="base_link" />
    <child
      link="head_right_link" />
    <axis
      xyz="0 0 -1" />
    <limit
      lower="-0.785"
      upper="0.785"
      effort="0"
      velocity="0" />
  </joint>
  <link
    name="head_right_wheel">
    <inertial>
      <origin
        xyz="2.2213E-07 -0.001561 -2.1706E-07"
        rpy="0 0 0" />
      <mass
        value="7.6316" />
      <inertia
        ixx="0.063665"
        ixy="3.9849E-08"
        ixz="2.0496E-08"
        iyy="0.1106"
        iyz="-3.9317E-08"
        izz="0.063665" />
    </inertial>
    <visual>
      <origin
        xyz="0 0 0"
        rpy="0 0 0" />
      <geometry>
        <mesh
          filename="package://autocar_urdf/meshes/visual/head_right_wheel.STL" />
      </geometry>
      <material
        name="">
        <color
          rgba="0 0 0 0.8" />
      </material>
    </visual>
    <collision>
      <origin
        xyz="0 0 0"
        rpy="0 0 0" />
      <geometry>
        <mesh
          filename="package://autocar_urdf/meshes/visual/head_right_wheel.STL" />
      </geometry>
    </collision>
  </link>
  <joint
    name="head_right_wheel_joint"
    type="continuous">
    <origin
      xyz="0 -0.066 -0.026"
      rpy="0 0 0" />
    <parent
      link="head_right_link" />
    <child
      link="head_right_wheel" />
    <axis
      xyz="0 1 0" />
  </joint>
  <link
    name="rear_left_wheel">
    <inertial>
      <origin
        xyz="1.8434E-06 0.0096501 -1.5658E-06"
        rpy="0 0 0" />
      <mass
        value="7.6673" />
      <inertia
        ixx="0.063698"
        ixy="-5.7552E-08"
        ixz="-1.674E-07"
        iyy="0.11067"
        iyz="4.1277E-08"
        izz="0.063698" />
    </inertial>
    <visual>
      <origin
        xyz="0 0 0"
        rpy="0 0 0" />
      <geometry>
        <mesh
          filename="package://autocar_urdf/meshes/visual/rear_left_wheel.STL" />
      </geometry>
      <material
        name="">
        <color
          rgba="0 0 0 0.8" />
      </material>
    </visual>
    <collision>
      <origin
        xyz="0 0 0"
        rpy="0 0 0" />
      <geometry>
        <mesh
          filename="package://autocar_urdf/meshes/visual/rear_left_wheel.STL" />
      </geometry>
    </collision>
  </link>
  <joint
    name="rear_left_wheel_joint"
    type="continuous">
    <origin
      xyz="-0.28008 0.29249 -0.1955"
      rpy="0 0 0" />
    <parent
      link="base_link" />
    <child
      link="rear_left_wheel" />
    <axis
      xyz="0 -1 0" />
  </joint>
  <link
    name="rear_right_wheel">
    <inertial>
      <origin
        xyz="-1.8371E-06 -0.019754 -1.5532E-06"
        rpy="0 0 0" />
      <mass
        value="7.706" />
      <inertia
        ixx="0.063725"
        ixy="-5.663E-08"
        ixz="1.6875E-07"
        iyy="0.11072"
        iyz="-4.0379E-08"
        izz="0.063725" />
    </inertial>
    <visual>
      <origin
        xyz="0 0 0"
        rpy="0 0 0" />
      <geometry>
        <mesh
          filename="package://autocar_urdf/meshes/visual/rear_right_wheel.STL" />
      </geometry>
      <material
        name="">
        <color
          rgba="0 0 0 0.8" />
      </material>
    </visual>
    <collision>
      <origin
        xyz="0 0 0"
        rpy="0 0 0" />
      <geometry>
        <mesh
          filename="package://autocar_urdf/meshes/visual/rear_right_wheel.STL" />
      </geometry>
    </collision>
  </link>
  <joint
    name="rear_right_wheel_joint"
    type="continuous">
    <origin
      xyz="-0.28009 -0.28251 -0.1955"
      rpy="0 0 0" />
    <parent
      link="base_link" />
    <child
      link="rear_right_wheel" />
    <axis
      xyz="0 1 0" />
  </joint>
  <link
    name="bracket_link">
    <inertial>
      <origin
        xyz="0.025384 1.3927E-06 0.02305"
        rpy="0 0 0" />
      <mass
        value="6.3125" />
      <inertia
        ixx="0.0962"
        ixy="6.5449E-19"
        ixz="-1.5879E-19"
        iyy="0.13912"
        iyz="-6.0653E-19"
        izz="0.095173" />
    </inertial>
    <visual>
      <origin
        xyz="0 0 0"
        rpy="0 0 0" />
      <geometry>
        <mesh
          filename="package://autocar_urdf/meshes/visual/bracket_link.STL" />
      </geometry>
      <material
        name="">
        <color
          rgba="1 1 0.52941 1" />
      </material>
    </visual>
    <collision>
      <origin
        xyz="0 0 0"
        rpy="0 0 0" />
      <geometry>
        <mesh
          filename="package://autocar_urdf/meshes/visual/bracket_link.STL" />
      </geometry>
    </collision>
  </link>
  <joint
    name="bracket_link_fix"
    type="fixed">
    <origin
      xyz="0.028915 -1.1431E-05 0.376"
      rpy="0 0 0" />
    <parent
      link="base_link" />
    <child
      link="bracket_link" />
    <axis
      xyz="0 0 0" />
  </joint>
  <link
    name="rear_wave">
    <inertial>
      <origin
        xyz="-0.01108 1.7275E-14 0.0013557"
        rpy="0 0 0" />
      <mass
        value="0.011233" />
      <inertia
        ixx="1.1553E-06"
        ixy="-1.0203E-19"
        ixz="-1.9378E-08"
        iyy="7.9902E-07"
        iyz="9.8424E-18"
        izz="1.4323E-06" />
    </inertial>
    <visual>
      <origin
        xyz="0 0 0"
        rpy="0 0 0" />
      <geometry>
        <mesh
          filename="package://autocar_urdf/meshes/visual/rear_wave.STL" />
      </geometry>
      <material
        name="">
        <color
          rgba="0.46275 0.46275 0.45882 1" />
      </material>
    </visual>
    <collision>
      <origin
        xyz="0 0 0"
        rpy="0 0 0" />
      <geometry>
        <mesh
          filename="package://autocar_urdf/meshes/visual/rear_wave.STL" />
      </geometry>
    </collision>
  </link>
  <joint
    name="rear_wave_fix"
    type="fixed">
    <origin
      xyz="-0.3385 0 -0.30895"
      rpy="0 0 3.1416" />
    <parent
      link="bracket_link" />
    <child
      link="rear_wave" />
    <axis
      xyz="0 0 0" />
  </joint>
  <link
    name="head_wave">
    <inertial>
      <origin
        xyz="-0.01108 2.3493E-09 0.0015365"
        rpy="0 0 0" />
      <mass
        value="0.011233" />
      <inertia
        ixx="1.1553E-06"
        ixy="5.0357E-13"
        ixz="1.9378E-08"
        iyy="7.9902E-07"
        iyz="1.6457E-11"
        izz="1.4323E-06" />
    </inertial>
    <visual>
      <origin
        xyz="0 0 0"
        rpy="0 0 0" />
      <geometry>
        <mesh
          filename="package://autocar_urdf/meshes/visual/head_wave.STL" />
      </geometry>
      <material
        name="">
        <color
          rgba="0.46275 0.46275 0.45882 1" />
      </material>
    </visual>
    <collision>
      <origin
        xyz="0 0 0"
        rpy="0 0 0" />
      <geometry>
        <mesh
          filename="package://autocar_urdf/meshes/visual/head_wave.STL" />
      </geometry>
    </collision>
  </link>
  <joint
    name="head_wave_fix"
    type="fixed">
    <origin
      xyz="0.3615 0 -0.30895"
      rpy="0 0 0" />
    <parent
      link="bracket_link" />
    <child
      link="head_wave" />
    <axis
      xyz="0 0 0" />
  </joint>
  <link
    name="head_steoreo_camera">
    <inertial>
      <origin
        xyz="0.011882 0.00028138 2.6917E-05"
        rpy="0 0 0" />
      <mass
        value="0.031104" />
      <inertia
        ixx="4.2892E-05"
        ixy="-2.6254E-08"
        ixz="-3.5979E-09"
        iyy="3.3444E-06"
        iyz="8.733E-08"
        izz="4.0211E-05" />
    </inertial>
    <visual>
      <origin
        xyz="0 0 0"
        rpy="0 0 0" />
      <geometry>
        <mesh
          filename="package://autocar_urdf/meshes/visual/head_steoreo_camera.STL" />
      </geometry>
      <material
        name="">
        <color
          rgba="0.79216 0.81961 0.93333 1" />
      </material>
    </visual>
    <collision>
      <origin
        xyz="0 0 0"
        rpy="0 0 0" />
      <geometry>
        <mesh
          filename="package://autocar_urdf/meshes/visual/head_steoreo_camera.STL" />
      </geometry>
    </collision>
  </link>
  <joint
    name="head_steoreo_camera_fix"
    type="fixed">
    <origin
      xyz="0.376 0 -0.2225"
      rpy="0 0 0" />
    <parent
      link="bracket_link" />
    <child
      link="head_steoreo_camera" />
    <axis
      xyz="0 0 0" />
  </joint>
  <link
    name="head_camera">
    <inertial>
      <origin
        xyz="-0.025397 0.00018741 -2.5801E-08"
        rpy="0 0 0" />
      <mass
        value="0.024913" />
      <inertia
        ixx="3.0822E-06"
        ixy="5.782E-08"
        ixz="2.3737E-12"
        iyy="3.0997E-06"
        iyz="-8.8167E-09"
        izz="3.1069E-06" />
    </inertial>
    <visual>
      <origin
        xyz="0 0 0"
        rpy="0 0 0" />
      <geometry>
        <mesh
          filename="package://autocar_urdf/meshes/visual/head_camera.STL" />
      </geometry>
      <material
        name="">
        <color
          rgba="0.79216 0.81961 0.93333 1" />
      </material>
    </visual>
    <collision>
      <origin
        xyz="0 0 0"
        rpy="0 0 0" />
      <geometry>
        <mesh
          filename="package://autocar_urdf/meshes/visual/head_camera.STL" />
      </geometry>
    </collision>
  </link>
  <joint
    name="head_camera_fix"
    type="fixed">
    <origin
      xyz="0.36648 0 0.384"
      rpy="0 0 0" />
    <parent
      link="bracket_link" />
    <child
      link="head_camera" />
    <axis
      xyz="0 0 0" />
  </joint>
  <link
    name="left_camera">
    <inertial>
      <origin
        xyz="-0.025397 0.00018741 -2.5801E-08"
        rpy="0 0 0" />
      <mass
        value="0.024913" />
      <inertia
        ixx="3.0822E-06"
        ixy="5.782E-08"
        ixz="2.3737E-12"
        iyy="3.0997E-06"
        iyz="-8.8167E-09"
        izz="3.1069E-06" />
    </inertial>
    <visual>
      <origin
        xyz="0 0 0"
        rpy="0 0 0" />
      <geometry>
        <mesh
          filename="package://autocar_urdf/meshes/visual/left_camera.STL" />
      </geometry>
      <material
        name="">
        <color
          rgba="0.79216 0.81961 0.93333 1" />
      </material>
    </visual>
    <collision>
      <origin
        xyz="0 0 0"
        rpy="0 0 0" />
      <geometry>
        <mesh
          filename="package://autocar_urdf/meshes/visual/left_camera.STL" />
      </geometry>
    </collision>
  </link>
  <joint
    name="left_camera_fix"
    type="fixed">
    <origin
      xyz="-0.029 0.23048 0.384"
      rpy="0 0 1.5708" />
    <parent
      link="bracket_link" />
    <child
      link="left_camera" />
    <axis
      xyz="0 0 0" />
  </joint>
  <link
    name="rear_camera">
    <inertial>
      <origin
        xyz="-0.025397 0.00018741 -2.5801E-08"
        rpy="0 0 0" />
      <mass
        value="0.024913" />
      <inertia
        ixx="3.0822E-06"
        ixy="5.782E-08"
        ixz="2.3737E-12"
        iyy="3.0997E-06"
        iyz="-8.8167E-09"
        izz="3.1069E-06" />
    </inertial>
    <visual>
      <origin
        xyz="0 0 0"
        rpy="0 0 0" />
      <geometry>
        <mesh
          filename="package://autocar_urdf/meshes/visual/rear_camera.STL" />
      </geometry>
      <material
        name="">
        <color
          rgba="0.79216 0.81961 0.93333 1" />
      </material>
    </visual>
    <collision>
      <origin
        xyz="0 0 0"
        rpy="0 0 0" />
      <geometry>
        <mesh
          filename="package://autocar_urdf/meshes/visual/rear_camera.STL" />
      </geometry>
    </collision>
  </link>
  <joint
    name="rear_camera_fix"
    type="fixed">
    <origin
      xyz="-0.34448 0 0.384"
      rpy="0 0 3.1416" />
    <parent
      link="bracket_link" />
    <child
      link="rear_camera" />
    <axis
      xyz="0 0 0" />
  </joint>
  <link
    name="right_camera">
    <inertial>
      <origin
        xyz="-0.025397 0.00018741 -2.5801E-08"
        rpy="0 0 0" />
      <mass
        value="0.024913" />
      <inertia
        ixx="3.0822E-06"
        ixy="5.782E-08"
        ixz="2.3737E-12"
        iyy="3.0997E-06"
        iyz="-8.8167E-09"
        izz="3.1069E-06" />
    </inertial>
    <visual>
      <origin
        xyz="0 0 0"
        rpy="0 0 0" />
      <geometry>
        <mesh
          filename="package://autocar_urdf/meshes/visual/right_camera.STL" />
      </geometry>
      <material
        name="">
        <color
          rgba="0.79216 0.81961 0.93333 1" />
      </material>
    </visual>
    <collision>
      <origin
        xyz="0 0 0"
        rpy="0 0 0" />
      <geometry>
        <mesh
          filename="package://autocar_urdf/meshes/visual/right_camera.STL" />
      </geometry>
    </collision>
  </link>
  <joint
    name="right_camera_fix"
    type="fixed">
    <origin
      xyz="-0.029 -0.23048 0.384"
      rpy="0 0 -1.5708" />
    <parent
      link="bracket_link" />
    <child
      link="right_camera" />
    <axis
      xyz="0 0 0" />
  </joint>
  <link
    name="lidar">
    <inertial>
      <origin
        xyz="0.00039 0.00029922 0.034077"
        rpy="0 0 0" />
      <mass
        value="0.092994" />
      <inertia
        ixx="7.9923E-05"
        ixy="1.8268E-07"
        ixz="-4.5401E-08"
        iyy="7.8642E-05"
        iyz="1.6532E-07"
        izz="0.0001288" />
    </inertial>
    <visual>
      <origin
        xyz="0 0 0"
        rpy="0 0 0" />
      <geometry>
        <mesh
          filename="package://autocar_urdf/meshes/visual/lidar.STL" />
      </geometry>
      <material
        name="">
        <color
          rgba="0.082353 0.082353 0.082353 1" />
      </material>
    </visual>
    <collision>
      <origin
        xyz="0 0 0"
        rpy="0 0 0" />
      <geometry>
        <mesh
          filename="package://autocar_urdf/meshes/visual/lidar.STL" />
      </geometry>
    </collision>
  </link>
  <joint
    name="lidar_joint"
    type="continuous">
    <origin
      xyz="0.011 0 0.5618"
      rpy="0 0 0" />
    <parent
      link="bracket_link" />
    <child
      link="lidar" />
    <axis
      xyz="0 0 -1" />
  </joint>
</robot>