<?xml version="1.0" encoding="utf-8"?>
<!-- This URDF was automatically created by SolidWorks to URDF Exporter! Originally created by Stephen Brawner (brawner@gmail.com) 
     Commit Version: 1.6.0-1-g15f4949  Build Version: 1.6.7594.29634
     For more information, please see http://wiki.ros.org/sw_urdf_exporter -->
<robot
  name="orbbec_car" xmlns:xacro="http://www.ros.org/wiki/xacro">

  <!-- Macro for rgb camera sensor -->
  <xacro:macro name="usb_camera" params="prefix">

      <gazebo reference="${prefix}_camera">
          <material>Gazebo/Black</material>
      </gazebo>

      <gazebo reference="${prefix}_camera">
          <sensor type="camera" name="camera_node">
              <update_rate>30.0</update_rate>
              <camera name="${prefix}">
                <horizontal_fov>2.058</horizontal_fov> <!-- 水平FOV，以弧度为单位 -->
                <vertical_fov>1.081</vertical_fov>     <!-- 垂直FOV，以弧度为单位 -->
                  <image>
                      <width>1920</width>
                      <height>1080</height>
                      <format>R8G8B8</format>
                  </image>
                  <clip>
                      <near>0.02</near>
                      <far>300</far>
                  </clip>
                  <noise>
                      <type>gaussian</type>
                      <mean>0.0</mean>
                      <stddev>0.007</stddev>
                  </noise>
              </camera>
            
            <plugin name="gazebo_camera" filename="libgazebo_ros_camera.so">
              <image_topic_name>image_raw</image_topic_name>
              <camera_info_topic_name>camera_info</camera_info_topic_name>
              <camera_name>${prefix}_color_camera</camera_name>
              <frame_name>${prefix}_camera</frame_name>
              <hack_baseline>0.2</hack_baseline>
            </plugin>
          </sensor>
      </gazebo>
  </xacro:macro>

  <!-- <pose> 0.0 0.0 0.0 0.0 0.0 0.0 </pose> -->

  <link
    name="base_link">
    <inertial>
      <origin
        xyz="-0.0082217 -0.015323 -0.13715"
        rpy="0 0 0" />
      <mass
        value="4.8424" />
      <inertia
        ixx="0.031547"
        ixy="-1.1952E-06"
        ixz="-0.0018897"
        iyy="0.098519"
        iyz="-4.9071E-07"
        izz="0.11312" />
    </inertial>
    <visual>
      <origin
        xyz="0 0 0"
        rpy="0 0 0" />
      <geometry>
        <mesh
          filename="/home/jiaozhu/Documents/code/ros2_dev_ws2/src/learning_gazebo/meshes/visual/base_link.STL" />
      </geometry>
      <material
        name="">
        <color
          rgba="0.79216 0.81961 0.93333 1" />
      </material>
    </visual>
    <collision>
      <origin
        xyz="0 0 0"
        rpy="0 0 0" />
      <geometry>
        <mesh
          filename="/home/jiaozhu/Documents/code/ros2_dev_ws2/src/learning_gazebo/meshes/visual/base_link.STL" />
      </geometry>
    </collision>
  </link>
  <link
    name="head_left_link">
    <inertial>
      <origin
        xyz="-5.5511E-17 0.023901 -0.02621"
        rpy="0 0 0" />
      <mass
        value="0.054143" />
      <inertia
        ixx="4.1055E-05"
        ixy="1.8886E-20"
        ixz="3.7564E-22"
        iyy="2.1346E-05"
        iyz="-1.5617E-07"
        izz="3.2352E-05" />
    </inertial>
    <visual>
      <origin
        xyz="0 0 0"
        rpy="0 0 0" />
      <geometry>
        <mesh
          filename="/home/jiaozhu/Documents/code/ros2_dev_ws2/src/learning_gazebo/meshes/visual/head_left_link.STL" />
      </geometry>
      <material
        name="">
        <color
          rgba="0.79216 0.81961 0.93333 1" />
      </material>
    </visual>
    <collision>
      <origin
        xyz="0 0 0"
        rpy="0 0 0" />
      <geometry>
        <mesh
          filename="/home/jiaozhu/Documents/code/ros2_dev_ws2/src/learning_gazebo/meshes/visual/head_left_link.STL" />
      </geometry>
    </collision>
  </link>
  <joint
    name="head_left_link_joint"
    type="revolute">
    <origin
      xyz="0.37142 0.23399 -0.1695"
      rpy="0 0 0" />
    <parent
      link="base_link" />
    <child
      link="head_left_link" />
    <axis
      xyz="0 0 -1" />
    <limit
      lower="-0.785"
      upper="0.785"
      effort="0"
      velocity="0" />
  </joint>
  <link
    name="head_left_wheel">
    <inertial>
      <origin
        xyz="-6.2782E-06 0.0016644 2.0084E-05"
        rpy="0 0 0" />
      <mass
        value="7.6662" />
      <inertia
        ixx="0.063692"
        ixy="-1.9954E-07"
        ixz="7.4231E-08"
        iyy="0.11066"
        iyz="2.6493E-08"
        izz="0.063692" />
    </inertial>
    <visual>
      <origin
        xyz="0 0 0"
        rpy="0 0 0" />
      <geometry>
        <mesh
          filename="/home/jiaozhu/Documents/code/ros2_dev_ws2/src/learning_gazebo/meshes/visual/head_left_wheel.STL" />
      </geometry>
      <material
        name="">
        <color
          rgba="0 0 0 0.8" />
      </material>
    </visual>
    <collision>
      <origin
        xyz="0 0 0"
        rpy="0 0 0" />
      <geometry>
        <mesh
          filename="/home/jiaozhu/Documents/code/ros2_dev_ws2/src/learning_gazebo/meshes/visual/head_left_wheel.STL" />
      </geometry>
    </collision>
  </link>
  <joint
    name="head_left_wheel_joint"
    type="continuous">
    <origin
      xyz="0 0.066 -0.026"
      rpy="0 0 0" />
    <parent
      link="head_left_link" />
    <child
      link="head_left_wheel" />
    <axis
      xyz="0 -1 0" />
  </joint>
  <link
    name="head_right_link">
    <inertial>
      <origin
        xyz="1.1102E-16 -0.023901 -0.02621"
        rpy="0 0 0" />
      <mass
        value="0.054143" />
      <inertia
        ixx="4.1055E-05"
        ixy="1.8982E-20"
        ixz="-3.0255E-22"
        iyy="2.1346E-05"
        iyz="1.5617E-07"
        izz="3.2352E-05" />
    </inertial>
    <visual>
      <origin
        xyz="0 0 0"
        rpy="0 0 0" />
      <geometry>
        <mesh
          filename="/home/jiaozhu/Documents/code/ros2_dev_ws2/src/learning_gazebo/meshes/visual/head_right_link.STL" />
      </geometry>
      <material
        name="">
        <color
          rgba="0.79216 0.81961 0.93333 1" />
      </material>
    </visual>
    <collision>
      <origin
        xyz="0 0 0"
        rpy="0 0 0" />
      <geometry>
        <mesh
          filename="/home/jiaozhu/Documents/code/ros2_dev_ws2/src/learning_gazebo/meshes/visual/head_right_link.STL" />
      </geometry>
    </collision>
  </link>
  <joint
    name="head_right_link_joint"
    type="revolute">
    <origin
      xyz="0.37142 -0.23401 -0.1695"
      rpy="0 0 0" />
    <parent
      link="base_link" />
    <child
      link="head_right_link" />
    <axis
      xyz="0 0 -1" />
    <limit
      lower="-0.785"
      upper="0.785"
      effort="0"
      velocity="0" />
  </joint>
  <link
    name="head_right_wheel">
    <inertial>
      <origin
        xyz="2.2213E-07 -0.001561 -2.1706E-07"
        rpy="0 0 0" />
      <mass
        value="7.6316" />
      <inertia
        ixx="0.063665"
        ixy="3.9849E-08"
        ixz="2.0496E-08"
        iyy="0.1106"
        iyz="-3.9317E-08"
        izz="0.063665" />
    </inertial>
    <visual>
      <origin
        xyz="0 0 0"
        rpy="0 0 0" />
      <geometry>
        <mesh
          filename="/home/jiaozhu/Documents/code/ros2_dev_ws2/src/learning_gazebo/meshes/visual/head_right_wheel.STL" />
      </geometry>
      <material
        name="">
        <color
          rgba="0 0 0 0.8" />
      </material>
    </visual>
    <collision>
      <origin
        xyz="0 0 0"
        rpy="0 0 0" />
      <geometry>
        <mesh
          filename="/home/jiaozhu/Documents/code/ros2_dev_ws2/src/learning_gazebo/meshes/visual/head_right_wheel.STL" />
      </geometry>
    </collision>
  </link>
  <joint
    name="head_right_wheel_joint"
    type="continuous">
    <origin
      xyz="0 -0.066 -0.026"
      rpy="0 0 0" />
    <parent
      link="head_right_link" />
    <child
      link="head_right_wheel" />
    <axis
      xyz="0 1 0" />
  </joint>
  <link
    name="rear_left_wheel">
    <inertial>
      <origin
        xyz="1.8434E-06 0.0096501 -1.5658E-06"
        rpy="0 0 0" />
      <mass
        value="7.6673" />
      <inertia
        ixx="0.063698"
        ixy="-5.7552E-08"
        ixz="-1.674E-07"
        iyy="0.11067"
        iyz="4.1277E-08"
        izz="0.063698" />
    </inertial>
    <visual>
      <origin
        xyz="0 0 0"
        rpy="0 0 0" />
      <geometry>
        <mesh
          filename="/home/jiaozhu/Documents/code/ros2_dev_ws2/src/learning_gazebo/meshes/visual/rear_left_wheel.STL" />
      </geometry>
      <material
        name="">
        <color
          rgba="0 0 0 0.8" />
      </material>
    </visual>
    <collision>
      <origin
        xyz="0 0 0"
        rpy="0 0 0" />
      <geometry>
        <mesh
          filename="/home/jiaozhu/Documents/code/ros2_dev_ws2/src/learning_gazebo/meshes/visual/rear_left_wheel.STL" />
      </geometry>
    </collision>
  </link>
  <joint
    name="rear_left_wheel_joint"
    type="continuous">
    <origin
      xyz="-0.28008 0.29249 -0.1955"
      rpy="0 0 0" />
    <parent
      link="base_link" />
    <child
      link="rear_left_wheel" />
    <axis
      xyz="0 -1 0" />
  </joint>
  <link
    name="rear_right_wheel">
    <inertial>
      <origin
        xyz="-1.8371E-06 -0.019754 -1.5532E-06"
        rpy="0 0 0" />
      <mass
        value="7.706" />
      <inertia
        ixx="0.063725"
        ixy="-5.663E-08"
        ixz="1.6875E-07"
        iyy="0.11072"
        iyz="-4.0379E-08"
        izz="0.063725" />
    </inertial>
    <visual>
      <origin
        xyz="0 0 0"
        rpy="0 0 0" />
      <geometry>
        <mesh
          filename="/home/jiaozhu/Documents/code/ros2_dev_ws2/src/learning_gazebo/meshes/visual/rear_right_wheel.STL" />
      </geometry>
      <material
        name="">
        <color
          rgba="0 0 0 0.8" />
      </material>
    </visual>
    <collision>
      <origin
        xyz="0 0 0"
        rpy="0 0 0" />
      <geometry>
        <mesh
          filename="/home/jiaozhu/Documents/code/ros2_dev_ws2/src/learning_gazebo/meshes/visual/rear_right_wheel.STL" />
      </geometry>
    </collision>
  </link>
  <joint
    name="rear_right_wheel_joint"
    type="continuous">
    <origin
      xyz="-0.28009 -0.28251 -0.1955"
      rpy="0 0 0" />
    <parent
      link="base_link" />
    <child
      link="rear_right_wheel" />
    <axis
      xyz="0 1 0" />
  </joint>
  <link
    name="bracket_link">
    <inertial>
      <origin
        xyz="0.025384 1.3927E-06 0.02305"
        rpy="0 0 0" />
      <mass
        value="6.3125" />
      <inertia
        ixx="0.0962"
        ixy="6.5449E-19"
        ixz="-1.5879E-19"
        iyy="0.13912"
        iyz="-6.0653E-19"
        izz="0.095173" />
    </inertial>
    <visual>
      <origin
        xyz="0 0 0"
        rpy="0 0 0" />
      <geometry>
        <mesh
          filename="/home/jiaozhu/Documents/code/ros2_dev_ws2/src/learning_gazebo/meshes/visual/bracket_link.STL" />
      </geometry>
      <material
        name="">
        <color
          rgba="1 1 0.52941 1" />
      </material>
    </visual>
    <collision>
      <origin
        xyz="0 0 0"
        rpy="0 0 0" />
      <geometry>
        <mesh
          filename="/home/jiaozhu/Documents/code/ros2_dev_ws2/src/learning_gazebo/meshes/visual/bracket_link.STL" />
      </geometry>
    </collision>
  </link>
  <joint
    name="bracket_link_fix"
    type="fixed">
    <origin
      xyz="0.028915 -1.1431E-05 0.376"
      rpy="0 0 0" />
    <parent
      link="base_link" />
    <child
      link="bracket_link" />
    <axis
      xyz="0 0 0" />
  </joint>
  <link
    name="rear_wave">
    <inertial>
      <origin
        xyz="-0.01108 1.7275E-14 0.0013557"
        rpy="0 0 0" />
      <mass
        value="0.011233" />
      <inertia
        ixx="1.1553E-06"
        ixy="-1.0203E-19"
        ixz="-1.9378E-08"
        iyy="7.9902E-07"
        iyz="9.8424E-18"
        izz="1.4323E-06" />
    </inertial>
    <visual>
      <origin
        xyz="0 0 0"
        rpy="0 0 0" />
      <geometry>
        <mesh
          filename="/home/jiaozhu/Documents/code/ros2_dev_ws2/src/learning_gazebo/meshes/visual/rear_wave.STL" />
      </geometry>
      <material
        name="">
        <color
          rgba="0.46275 0.46275 0.45882 1" />
      </material>
    </visual>
    <collision>
      <origin
        xyz="0 0 0"
        rpy="0 0 0" />
      <geometry>
        <mesh
          filename="/home/jiaozhu/Documents/code/ros2_dev_ws2/src/learning_gazebo/meshes/visual/rear_wave.STL" />
      </geometry>
    </collision>
  </link>
  <joint
    name="rear_wave_fix"
    type="fixed">
    <origin
      xyz="-0.3385 0 -0.30895"
      rpy="0 0 3.1416" />
    <parent
      link="bracket_link" />
    <child
      link="rear_wave" />
    <axis
      xyz="0 0 0" />
  </joint>
  <link
    name="head_wave">
    <inertial>
      <origin
        xyz="-0.01108 2.3493E-09 0.0015365"
        rpy="0 0 0" />
      <mass
        value="0.011233" />
      <inertia
        ixx="1.1553E-06"
        ixy="5.0357E-13"
        ixz="1.9378E-08"
        iyy="7.9902E-07"
        iyz="1.6457E-11"
        izz="1.4323E-06" />
    </inertial>
    <visual>
      <origin
        xyz="0 0 0"
        rpy="0 0 0" />
      <geometry>
        <mesh
          filename="/home/jiaozhu/Documents/code/ros2_dev_ws2/src/learning_gazebo/meshes/visual/head_wave.STL" />
      </geometry>
      <material
        name="">
        <color
          rgba="0.46275 0.46275 0.45882 1" />
      </material>
    </visual>
    <collision>
      <origin
        xyz="0 0 0"
        rpy="0 0 0" />
      <geometry>
        <mesh
          filename="/home/jiaozhu/Documents/code/ros2_dev_ws2/src/learning_gazebo/meshes/visual/head_wave.STL" />
      </geometry>
    </collision>
  </link>
  <joint
    name="head_wave_fix"
    type="fixed">
    <origin
      xyz="0.3615 0 -0.30895"
      rpy="0 0 0" />
    <parent
      link="bracket_link" />
    <child
      link="head_wave" />
    <axis
      xyz="0 0 0" />
  </joint>
  <link
    name="head_steoreo_camera">
    <inertial>
      <origin
        xyz="0.011882 0.00028138 2.6917E-05"
        rpy="0 0 0" />
      <mass
        value="0.031104" />
      <inertia
        ixx="4.2892E-05"
        ixy="-2.6254E-08"
        ixz="-3.5979E-09"
        iyy="3.3444E-06"
        iyz="8.733E-08"
        izz="4.0211E-05" />
    </inertial>
    <visual>
      <origin
        xyz="0 0 0"
        rpy="0 0 0" />
      <geometry>
        <mesh
          filename="/home/jiaozhu/Documents/code/ros2_dev_ws2/src/learning_gazebo/meshes/visual/head_steoreo_camera.STL" />
      </geometry>
      <material
        name="">
        <color
          rgba="0.79216 0.81961 0.93333 1" />
      </material>
    </visual>
    <collision>
      <origin
        xyz="0 0 0"
        rpy="0 0 0" />
      <geometry>
        <mesh
          filename="/home/jiaozhu/Documents/code/ros2_dev_ws2/src/learning_gazebo/meshes/visual/head_steoreo_camera.STL" />
      </geometry>
    </collision>
  </link>
  <joint
    name="head_steoreo_camera_fix"
    type="fixed">
    <origin
      xyz="0.376 0 -0.2225"
      rpy="0 0 0" />
    <parent
      link="bracket_link" />
    <child
      link="head_steoreo_camera" />
    <axis
      xyz="0 0 0" />
  </joint>
  <link
    name="head_camera">
    <inertial>
      <origin
        xyz="-0.025397 0.00018741 -2.5801E-08"
        rpy="0 0 0" />
      <mass
        value="0.024913" />
      <inertia
        ixx="3.0822E-06"
        ixy="5.782E-08"
        ixz="2.3737E-12"
        iyy="3.0997E-06"
        iyz="-8.8167E-09"
        izz="3.1069E-06" />
    </inertial>
    <visual>
      <origin
        xyz="0 0 0"
        rpy="0 0 0" />
      <geometry>
        <mesh
          filename="/home/jiaozhu/Documents/code/ros2_dev_ws2/src/learning_gazebo/meshes/visual/head_camera.STL" />
      </geometry>
      <material
        name="">
        <color
          rgba="0.79216 0.81961 0.93333 1" />
      </material>
    </visual>
    <collision>
      <origin
        xyz="0 0 0"
        rpy="0 0 0" />
      <geometry>
        <mesh
          filename="/home/jiaozhu/Documents/code/ros2_dev_ws2/src/learning_gazebo/meshes/visual/head_camera.STL" />
      </geometry>
    </collision>
  </link>
  <joint
    name="head_camera_fix"
    type="fixed">
    <origin
      xyz="0.36648 0 0.384"
      rpy="0 0 0" />
    <parent
      link="bracket_link" />
    <child
      link="head_camera" />
    <axis
      xyz="0 0 0" />
  </joint>
  <link
    name="left_camera">
    <inertial>
      <origin
        xyz="-0.025397 0.00018741 -2.5801E-08"
        rpy="0 0 0" />
      <mass
        value="0.024913" />
      <inertia
        ixx="3.0822E-06"
        ixy="5.782E-08"
        ixz="2.3737E-12"
        iyy="3.0997E-06"
        iyz="-8.8167E-09"
        izz="3.1069E-06" />
    </inertial>
    <visual>
      <origin
        xyz="0 0 0"
        rpy="0 0 0" />
      <geometry>
        <mesh
          filename="/home/jiaozhu/Documents/code/ros2_dev_ws2/src/learning_gazebo/meshes/visual/left_camera.STL" />
      </geometry>
      <material
        name="">
        <color
          rgba="0.79216 0.81961 0.93333 1" />
      </material>
    </visual>
    <collision>
      <origin
        xyz="0 0 0"
        rpy="0 0 0" />
      <geometry>
        <mesh
          filename="/home/jiaozhu/Documents/code/ros2_dev_ws2/src/learning_gazebo/meshes/visual/left_camera.STL" />
      </geometry>
    </collision>
  </link>
  <joint
    name="left_camera_fix"
    type="fixed">
    <origin
      xyz="-0.029 0.23048 0.384"
      rpy="0 0 1.5708" />
    <parent
      link="bracket_link" />
    <child
      link="left_camera" />
    <axis
      xyz="0 0 0" />
  </joint>
  <link
    name="rear_camera">
    <inertial>
      <origin
        xyz="-0.025397 0.00018741 -2.5801E-08"
        rpy="0 0 0" />
      <mass
        value="0.024913" />
      <inertia
        ixx="3.0822E-06"
        ixy="5.782E-08"
        ixz="2.3737E-12"
        iyy="3.0997E-06"
        iyz="-8.8167E-09"
        izz="3.1069E-06" />
    </inertial>
    <visual>
      <origin
        xyz="0 0 0"
        rpy="0 0 0" />
      <geometry>
        <mesh
          filename="/home/jiaozhu/Documents/code/ros2_dev_ws2/src/learning_gazebo/meshes/visual/rear_camera.STL" />
      </geometry>
      <material
        name="">
        <color
          rgba="0.79216 0.81961 0.93333 1" />
      </material>
    </visual>
    <collision>
      <origin
        xyz="0 0 0"
        rpy="0 0 0" />
      <geometry>
        <mesh
          filename="/home/jiaozhu/Documents/code/ros2_dev_ws2/src/learning_gazebo/meshes/visual/rear_camera.STL" />
      </geometry>
    </collision>
  </link>
  <joint
    name="rear_camera_fix"
    type="fixed">
    <origin
      xyz="-0.34448 0 0.384"
      rpy="0 0 3.1416" />
    <parent
      link="bracket_link" />
    <child
      link="rear_camera" />
    <axis
      xyz="0 0 0" />
  </joint>
  <link
    name="right_camera">
    <inertial>
      <origin
        xyz="-0.025397 0.00018741 -2.5801E-08"
        rpy="0 0 0" />
      <mass
        value="0.024913" />
      <inertia
        ixx="3.0822E-06"
        ixy="5.782E-08"
        ixz="2.3737E-12"
        iyy="3.0997E-06"
        iyz="-8.8167E-09"
        izz="3.1069E-06" />
    </inertial>
    <visual>
      <origin
        xyz="0 0 0"
        rpy="0 0 0" />
      <geometry>
        <mesh
          filename="/home/jiaozhu/Documents/code/ros2_dev_ws2/src/learning_gazebo/meshes/visual/right_camera.STL" />
      </geometry>
      <material
        name="">
        <color
          rgba="0.79216 0.81961 0.93333 1" />
      </material>
    </visual>
    <collision>
      <origin
        xyz="0 0 0"
        rpy="0 0 0" />
      <geometry>
        <mesh
          filename="/home/jiaozhu/Documents/code/ros2_dev_ws2/src/learning_gazebo/meshes/visual/right_camera.STL" />
      </geometry>
    </collision>
  </link>
  <joint
    name="right_camera_fix"
    type="fixed">
    <origin
      xyz="-0.029 -0.23048 0.384"
      rpy="0 0 -1.5708" />
    <parent
      link="bracket_link" />
    <child
      link="right_camera" />
    <axis
      xyz="0 0 0" />
  </joint>
  <link
    name="lidar">
    <inertial>
      <origin
        xyz="0.00039 0.00029922 0.034077"
        rpy="0 0 0" />
      <mass
        value="0.092994" />
      <inertia
        ixx="7.9923E-05"
        ixy="1.8268E-07"
        ixz="-4.5401E-08"
        iyy="7.8642E-05"
        iyz="1.6532E-07"
        izz="0.0001288" />
    </inertial>
    <visual>
      <origin
        xyz="0 0 0"
        rpy="0 0 0" />
      <geometry>
        <mesh
          filename="/home/jiaozhu/Documents/code/ros2_dev_ws2/src/learning_gazebo/meshes/visual/lidar.STL" />
      </geometry>
      <material
        name="">
        <color
          rgba="0.082353 0.082353 0.082353 1" />
      </material>
    </visual>
    <collision>
      <origin
        xyz="0 0 0"
        rpy="0 0 0" />
      <geometry>
        <mesh
          filename="/home/jiaozhu/Documents/code/ros2_dev_ws2/src/learning_gazebo/meshes/visual/lidar.STL" />
      </geometry>
    </collision>
  </link>
  <joint
    name="lidar_joint"
    type="continuous">
    <origin
      xyz="0.011 0 0.5618"
      rpy="0 0 0" />
    <parent
      link="bracket_link" />
    <child
      link="lidar" />
    <axis
      xyz="0 0 -1" />
  </joint>

  <!-- gazebo plugin gravity color -->
  <gazebo reference="base_link">
    <mu1 value="0.0"/>
    <mu2 value="0.0"/>
    <!-- <turnGravityOff>false </turnGravityOff> -->
    <material>Gazebo/ZincYellow</material>
  </gazebo>

  <!-- gazebo plugin gravity color -->
  <gazebo reference="bracket_link">
    <!-- <turnGravityOff>true </turnGravityOff> -->
    <material>Gazebo/White</material>
  </gazebo>

  <!-- gazebo color and friction -->
  <gazebo reference="head_left_wheel">
    <!-- <turnGravityOff>false </turnGravityOff>   -->
    <material>Gazebo/Grey</material>
    <mu1 value="0.0"/>
    <mu2 value="0.0"/>
    <!-- <kp  value="10000000.0" />
    <kd  value="1.0" />
    <fdir1 value="0 0 1"/> -->
  </gazebo>

  <gazebo reference="head_right_wheel">
    <material>Gazebo/Grey</material>
    <!-- <turnGravityOff>false </turnGravityOff>       -->
    <mu1 value="0.0"/>
    <mu2 value="0.0"/>
    <!-- <kp  value="10000000.0" />
    <kd  value="1.0" />
    <fdir1 value="0 0 1"/> -->
  </gazebo>

  <gazebo reference="rear_left_wheel">
    <material>Gazebo/Grey</material>
    <!-- <turnGravityOff>false </turnGravityOff>       -->
    <mu1 value="2.0"/>
    <mu2 value="2.0"/>
    <!-- <kp  value="10000000.0" />
    <kd  value="1.0" />
    <fdir1 value="1 0 0"/> -->
  </gazebo>

  <gazebo reference="rear_right_wheel">
    <material>Gazebo/Grey</material>
    <!-- <turnGravityOff>false </turnGravityOff>       -->
    <mu1 value="2.0"/>
    <mu2 value="2.0"/>
    <!-- <kp  value="10000000.0" />
    <kd  value="1.0" />
    <fdir1 value="1 0 0"/> -->
  </gazebo>

  <!-- ackmann driver model -->


  <!-- laser sensor -->
  <gazebo reference="lidar">
      <material>Gazebo/Black</material>
      <sensor type="ray" name="rplidar">
          <pose>0 0 0 0 0 0</pose>
          <visualize>true</visualize>
          <update_rate>5.5</update_rate>
          <ray>
              <scan>
                <horizontal>
                  <samples>360</samples>
                  <resolution>1</resolution>
                  <min_angle>-3</min_angle>
                  <max_angle>3</max_angle>
                </horizontal>
              </scan>
              <range>
                <min>0.10</min>
                <max>6.0</max>
                <resolution>0.01</resolution>
              </range>
              <noise>
                <type>gaussian</type>
                <mean>0.0</mean>
                <stddev>0.01</stddev>
              </noise>
          </ray>
          <plugin name="gazebo_rplidar" filename="libgazebo_ros_ray_sensor.so">
          <ros>
            <remapping> ~/out:=scan </remapping>
          </ros>
              <laser_topic_name>scan</laser_topic_name>
              <frame_name>lidar</frame_name>
              <output_type>sensor_msgs/LaserScan</output_type>
          </plugin>
      </sensor>
  </gazebo>

  <!-- color camera sensor -->
  <xacro:usb_camera prefix="head"/>
  <xacro:usb_camera prefix="left"/>
  <xacro:usb_camera prefix="rear"/>
  <xacro:usb_camera prefix="right"/>

  <!-- imu sensor-->
  <gazebo reference="head_steoreo_camera">
    <material>Gazebo/Black</material>
    <sensor name="imu_sensor" type="imu">
      <plugin filename="libgazebo_ros_imu_sensor.so" name="imu_plugin">
        <ros>
          <remapping>~/out:=imu</remapping>
        </ros>
        <initial_orientation_as_reference>false</initial_orientation_as_reference>
      </plugin>

      <always_on>true</always_on>
      <update_rate>60</update_rate>
      <visualize>true</visualize>
      <imu>
        <angular_velocity>
          <x>
            <noise type="gaussian">
              <mean>0.0</mean>
              <stddev>2e-4</stddev>
              <bias_mean>0.0000075</bias_mean>
              <bias_stddev>0.0000008</bias_stddev>
            </noise>
          </x>
          <y>
            <noise type="gaussian">
              <mean>0.0</mean>
              <stddev>2e-4</stddev>
              <bias_mean>0.0000075</bias_mean>
              <bias_stddev>0.0000008</bias_stddev>
            </noise>
          </y>
          <z>
            <noise type="gaussian">
              <mean>0.0</mean>
              <stddev>2e-4</stddev>
              <bias_mean>0.0000075</bias_mean>
              <bias_stddev>0.0000008</bias_stddev>
            </noise>
          </z>
        </angular_velocity>
        <linear_acceleration>
          <x>
            <noise type="gaussian">
              <mean>0.0</mean>
              <stddev>1.7e-2</stddev>
              <bias_mean>0.1</bias_mean>
              <bias_stddev>0.001</bias_stddev>
            </noise>
          </x>
          <y>
            <noise type="gaussian">
              <mean>0.0</mean>
              <stddev>1.7e-2</stddev>
              <bias_mean>0.1</bias_mean>
              <bias_stddev>0.001</bias_stddev>
            </noise>
          </y>
          <z>
            <noise type="gaussian">
              <mean>0.0</mean>
              <stddev>1.7e-2</stddev>
              <bias_mean>0.1</bias_mean>
              <bias_stddev>0.001</bias_stddev>
            </noise>
          </z>
        </linear_acceleration>
      </imu>
    </sensor>
  </gazebo>

  <!-- depth camera sensor -->
  <gazebo reference="head_steoreo_camera">
    <sensor type="depth" name="kinect">
        <always_on>true</always_on>
        <update_rate>15.0</update_rate>
        <pose>0 0 0 0 0 0</pose>
        <camera name="kinect">
            <horizontal_fov>1.587</horizontal_fov>
            <vertical_fov>1.15</vertical_fov>             
            <image>
                <format>R8G8B8</format>
                <width>1280</width>
                <height>800</height>
            </image>
            <clip>
                <near>0.05</near>
                <far>10.0</far>
            </clip>
        </camera>
        <plugin name="kinect_controller" filename="libgazebo_ros_camera.so">
          <ros>
            <remapping>depth_camera/image_raw:=rgb/image_raw</remapping>
            <remapping>depth_camera/image_depth:=depth/image_raw</remapping>
            <remapping>depth_camera/camera_info:=rgb/camera_info</remapping>
            <remapping>depth_camera/camera_info_depth:=depth/camera_info</remapping>
            <remapping>depth_camera/points:=depth/points</remapping>
          </ros>
          <camera_name>head_depth_camera</camera_name>
          <frame_name>head_steoreo_camera</frame_name>
          <hack_baseline>0.07</hack_baseline>
          <min_depth>0.001</min_depth>
          <max_depth>300.0</max_depth>
        </plugin>
    </sensor>
  </gazebo>

  <!-- head super wave sensor -->
  <gazebo reference="head_wave">
    <material>Gazebo/Black</material>
    <sensor type="ray" name="head_ultrasonic_sensor">
      <pose>0 0 0 0 0 0</pose>
      <!-- 是否可视化，gazebo里能不能看到 -->
      <visualize>true</visualize>
      <!-- 扫描速率，也就是数据更新速率 -->
      <update_rate>30</update_rate>
      <ray>
        <scan>
          <!-- 水平扫描的点数 -->
          <horizontal>
            <samples>30</samples>
            <resolution>1</resolution>
            <min_angle>-0.523</min_angle>
            <max_angle>0.523</max_angle>
          </horizontal>
          <!-- 垂直方向扫描的点数 -->
          <vertical>
            <samples>5</samples>
            <resolution>1</resolution>
            <min_angle>-0.01</min_angle>
            <max_angle>0.01</max_angle>
          </vertical>
        </scan>
        <!-- 超声波检测的范围和数据分辨率单位m -->
        <range>
          <min>0.025</min>
          <max>0.45</max>
          <resolution>0.001</resolution>
        </range>
        <!-- 数据噪声采用高斯噪声 -->
        <noise>
          <type>gaussian</type>
          <mean>0.0</mean>
          <stddev>0.01</stddev>
        </noise>
      </ray>
      <plugin name="head_ultrasonic_sensor_controller" filename="libgazebo_ros_ray_sensor.so">
        <ros>
          <!-- 重映射输出的话题名称 -->
          <remapping>~/out:=head_ultrasonic</remapping>
        </ros>
        <!-- 输出消息的类型，注意与雷达区分，这里是sensor_msgs/Range -->
        <output_type>sensor_msgs/Range</output_type>
        <!-- 射线类型，这里要写ultrasound，注意和雷达区分 -->
        <radiation_type>ultrasound</radiation_type>
        <!-- frame名称，填写link名称即可 -->
        <frame_name>head_wave</frame_name>
      </plugin>
    </sensor>
  </gazebo>

  <!-- rear super wave sensor -->
  <gazebo reference="rear_wave">
    <material>Gazebo/Black</material>  
    <sensor type="ray" name="rear_ultrasonic_sensor">
      <pose>0 0 0 0 0 0</pose>
      <!-- 是否可视化，gazebo里能不能看到 -->
      <visualize>true</visualize>
      <!-- 扫描速率，也就是数据更新速率 -->
      <update_rate>30</update_rate>
      <ray>
        <scan>
          <!-- 水平扫描的点数 -->
          <horizontal>
            <samples>30</samples>
            <resolution>1</resolution>
            <min_angle>-0.523</min_angle>
            <max_angle>0.523</max_angle>
          </horizontal>
          <!-- 垂直方向扫描的点数 -->
          <vertical>
            <samples>5</samples>
            <resolution>1</resolution>
            <min_angle>-0.01</min_angle>
            <max_angle>0.01</max_angle>
          </vertical>
        </scan>
        <!-- 超声波检测的范围和数据分辨率单位m -->
        <range>
          <min>0.025</min>
          <max>0.45</max>
          <resolution>0.001</resolution>
        </range>
        <!-- 数据噪声采用高斯噪声 -->
        <noise>
          <type>gaussian</type>
          <mean>0.0</mean>
          <stddev>0.01</stddev>
        </noise>
      </ray>
      <plugin name="rear_ultrasonic_sensor_controller" filename="libgazebo_ros_ray_sensor.so">
        <ros>
          <!-- 重映射输出的话题名称 -->
          <remapping>~/out:=rear_ultrasonic</remapping>
        </ros>
        <!-- 输出消息的类型，注意与雷达区分，这里是sensor_msgs/Range -->
        <output_type>sensor_msgs/Range</output_type>
        <!-- 射线类型，这里要写ultrasound，注意和雷达区分 -->
        <radiation_type>ultrasound</radiation_type>
        <!-- frame名称，填写link名称即可 -->
        <frame_name>rear_wave</frame_name>
      </plugin>
    </sensor>
  </gazebo>

</robot>